I'm sorry, but an uncaught exception occurred.

While running game code:
  File "game/script.rpy", line 133, in script
    "arrogante":
Exception: Sayer 'p' is not defined.

-- Full Traceback ------------------------------------------------------------

Full traceback:
  File "game/script.rpy", line 133, in script
    "arrogante":
  File "/Applications/renpy-8.3.2-sdk/renpy/ast.py", line 2573, in execute
    Say.execute(self)
  File "/Applications/renpy-8.3.2-sdk/renpy/ast.py", line 575, in execute
    who = eval_who(self.who, self.who_fast)
  File "/Applications/renpy-8.3.2-sdk/renpy/ast.py", line 464, in eval_who
    raise Exception("Sayer '%s' is not defined." % who)
Exception: Sayer 'p' is not defined.

macOS-14.4.1-arm64-arm-64bit arm64
Ren'Py 8.3.2.24090902
Projeto Ola Mundos 1.0
Tue Nov 19 10:45:31 2024
